Workbook

Sheet Assumptions
A1: Superior Wireless Auctions (B-Stock) — iPhone Lot Pricing
B4: 0.02 | C4: <-- Blue text on yellow = the only cell you edit. All totals recalculate from it.
A5: eBay selling fee applied to eBay resale prices | B5: 0 | C5: <-- 0% = gross resale, as requested. Set to ~13% to model real eBay fees.
A7: HOW THE NUMBERS ARE BUILT
A8: Bulk Price = the lot's Current bid on the auction page (what the lot costs at that bid).
A9: Fee @ 2% = Bulk Price x 2%.
A10: Total Excl. Shipping = Bulk Price + Fee. Excludes shipping, tax, and any other charges.
A11: Cost Per Unit = Total Excl. Shipping / Units.
A13: ASSUMPTIONS AND CAVEATS
A14: 1. "Multiply bulk price by 2%" is read as a 2% buyer fee ADDED to the bulk price.
A15: The standalone 2% amount is also shown in its own column if you meant the fee alone.
A16: 2. Source page shows lots 1-96 of 208 (page 1 of 3). Pages 2 and 3 are NOT in this file.
A17: 3. These are LIVE auctions. Current bid rises with each new bid, so every price here is a
A18: snapshot from the saved page, not a settled cost.
A19: 4. Shipping is excluded, per request. B-Stock lots ship from Dallas, TX.
... A27: Saved page supplied by user; captured 2026-08-02.

Sheet Auction Inventory
A1: Auction ID | B1: iPhone Model | C1: Storage | D1: Grade | E1: Units | F1: Carrier | G1: Handset Only | H1: Bulk Price (Current Bid) | I1: Site Avg $/Unit | J1: Fee @ 2% | K1: Total Excl. Shipping | L1: Cost Per Unit | M1: Bids | N1: Closes In | O1: Location | P1: Auction Link
A2: 50370 | B2: iPhone 17 Pro Max | C2: 512GB | D2: New | E2: 20 | F2: T-Mobile | G2: Yes | H2: 21200 | I2: 1060 | J2: =H2*Assumptions!$B$4 -> 424 | K2: =H2+J2 -> 21624 | L2: =IF(E2=0,"",K2/E2) -> 1081.2 | M2: 24 | N2: 1d 8h | O2: Dallas, TX | P2: https://bstock.com/superior/auction/auction/view/id/50370/
A3: 50424 | B3: iPhone 17 Pro Max | C3: 256GB | D3: A | E3: 20 | F3: Generic | G3: No | H3: 16050 | I3: 802.5 | J3: =H3*Assumptions!$B$4 -> 321 | K3: =H3+J3 -> 16371 | L3: =IF(E3=0,"",K3/E3) -> 818.55 | M3: 4 | N3: 1d 8h | O3: Dallas, TX | P3: https://bstock.com/superior/auction/auction/view/id/50424/
A4: 50429 | B4: iPhone 17 Pro | C4: 256GB | D4: B | E4: 20 | F4: Generic | G4: No | H4: 13050 | I4: 652.5 | J4: =H4*Assumptions!$B$4 -> 261 | K4: =H4+J4 -> 13311 | L4: =IF(E4=0,"",K4/E4) -> 665.55 | M4: 7 | N4: 1d 8h | O4: Dallas, TX | P4: https://bstock.com/superior/auction/auction/view/id/50429/
A5: 50423 | B5: iPhone 17 | C5: 512GB | D5: A | E5: 20 | F5: T-Mobile | G5: No | H5: 11050 | I5: 552.5 | J5: =H5*Assumptions!$B$4 -> 221 | K5: =H5+J5 -> 11271 | L5: =IF(E5=0,"",K5/E5) -> 563.55 | M5: 4 | N5: 1d 8h | O5: Dallas, TX | P5: https://bstock.com/superior/auction/auction/view/id/50423/
A6: 50427 | B6: iPhone 17 | C6: 256GB | D6: A | E6: 20 | F6: AT&T | G6: No | H6: 8500 | I6: 425 | J6: =H6*Assumptions!$B$4 -> 170 | K6: =H6+J6 -> 8670 | L6: =IF(E6=0,"",K6/E6) -> 433.5 | M6: 0 | N6: 1d 8h | O6: Dallas, TX | P6: https://bstock.com/superior/auction/auction/view/id/50427/
A7: 50422 | B7: iPhone 17 | C7: 256GB | D7: B | E7: 20 | F7: AT&T | G7: No | H7: 8000 | I7: 400 | J7: =H7*Assumptions!$B$4 -> 160 | K7: =H7+J7 -> 8160 | L7: =IF(E7=0,"",K7/E7) -> 408 | M7: 1 | N7: 1d 8h | O7: Dallas, TX | P7: https://bstock.com/superior/auction/auction/view/id/50422/
A8: 50428 | B8: iPhone 17 | C8: 256GB | D8: C | E8: 20 | F8: AT&T | G8: No | H8: 7800 | I8: 390 | J8: =H8*Assumptions!$B$4 -> 156 | K8: =H8+J8 -> 7956 | L8: =IF(E8=0,"",K8/E8) -> 397.8 | M8: 0 | N8: 1d 8h | O8: Dallas, TX | P8: https://bstock.com/superior/auction/auction/view/id/50428/
A9: 50412 | B9: iPhone 16 Pro Max | C9: 1TB | D9: C | E9: 20 | F9: AT&T | G9: No | H9: 12000 | I9: 600 | J9: =H9*Assumptions!$B$4 -> 240 | K9: =H9+J9 -> 12240 | L9: =IF(E9=0,"",K9/E9) -> 612 | M9: 2 | N9: 1d 8h | O9: Dallas, TX | P9: https://bstock.com/superior/auction/auction/view/id/50412/
A10: 50416 | B10: iPhone 16 Pro Max | C10: 512GB | D10: A | E10: 20 | F10: AT&T | G10: No | H10: 12000 | I10: 600 | J10: =H10*Assumptions!$B$4 -> 240 | K10: =H10+J10 -> 12240 | L10: =IF(E10=0,"",K10/E10) -> 612 | M10: 5 | N10: 1d 8h | O10: Dallas, TX | P10: https://bstock.com/superior/auction/auction/view/id/50416/
A11: 50411 | B11: iPhone 16 Pro Max | C11: 256GB | D11: A | E11: 20 | F11: Generic | G11: No | H11: 11150 | I11: 557.5 | J11: =H11*Assumptions!$B$4 -> 223 | K11: =H11+J11 -> 11373 | L11: =IF(E11=0,"",K11/E11) -> 568.65 | M11: 8 | N11: 1d 8h | O11: Dallas, TX | P11: https://bstock.com/superior/auction/auction/view/id/50411/
A12: 50417 | B12: iPhone 16 Pro Max | C12: 256GB | D12: B | E12: 20 | F12: Generic | G12: No | H12: 10200 | I12: 510 | J12: =H12*Assumptions!$B$4 -> 204 | K12: =H12+J12 -> 10404 | L12: =IF(E12=0,"",K12/E12) -> 520.2 | M12: 2 | N12: 1d 8h | O12: Dallas, TX | P12: https://bstock.com/superior/auction/auction/view/id/50417/
A13: 50410 | B13: iPhone 16 Pro | C13: 512GB | D13: B | E13: 20 | F13: T-Mobile | G13: No | H13: 8938 | I13: 446.9 | J13: =H13*Assumptions!$B$4 -> 178.76 | K13: =H13+J13 -> 9116.76 | L13: =IF(E13=0,"",K13/E13) -> 455.838 | M13: 3 | N13: 1d 9h | O13: Dallas, TX | P13: https://bstock.com/superior/auction/auction/view/id/50410/
... A97: 50361 | B97: iPhone XR, iPhone SE (2020), iPhone SE (2022) & More | C97: Mixed / Not specified | D97: B/C | E97: 50 | F97: Mixed Carrier | G97: No | H97: 610 | I97: 12.2 | J97: =H97*Assumptions!$B$4 -> 12.2 | K97: =H97+J97 -> 622.2 | L97: =IF(E97=0,"",K97/E97) -> 12.444 | M97: 4 | N97: 1d 9h | O97: Dallas, TX | P97: https://bstock.com/superior/auction/auction/view/id/50361/
A98: TOTAL / BLENDED | E98: =SUM(E2:E97) -> 8732 | H98: =SUM(H2:H97) -> 1686225 | J98: =SUM(J2:J97) -> 33724.5 | K98: =SUM(K2:K97) -> 1719949.5 | L98: =IF(E98=0,"",K98/E98) -> 196.97085 | M98: <- blended cost per unit across all lots on this page

Sheet Profit Potential
A1: Auction ID | B1: iPhone Model | C1: Storage | D1: Grade | E1: Carrier | F1: Units | G1: Cost Per Unit | H1: eBay Comps (n) | I1: eBay Min | J1: eBay Median | K1: eBay Max | L1: Cashout Cond | M1: Cashout Vendors (n) | N1: Cashout Min | O1: Cashout Max | P1: Profit/Unit @ Cashout Min | Q1: Profit/Unit @ Cashout Max | R1: Profit/Unit @ eBay Min | S1: Profit/Unit @ eBay Max | T1: Total @ Cashout Min | U1: Total @ Cashout Max | V1: Total @ eBay Min | W1: Total @ eBay Max | X1: Comp Conditions Used | Y1: Comp Lock Mix | Z1: Match Warning
A2: 50370 | B2: iPhone 17 Pro Max | C2: 512GB | D2: New | E2: T-Mobile | F2: 20 | G2: ='Auction Inventory'!L2 -> 1081.2 | H2: 3 | I2: 1199 | J2: 1442.49 | K2: 1479 | L2: MINT | M2: 14 | N2: 876 | O2: 1039 | P2: =IF(N2="","",N2-$G2) -> -205.2 | Q2: =IF(O2="","",O2-$G2) -> -42.2 | R2: =IF(I2="","",I2*(1-Assumptions!$B$5)-$G2) -> 117.8 | S2: =IF(K2="","",K2*(1-Assumptions!$B$5)-$G2) -> 397.8 | T2: =IF(P2="","",P2*$F2) -> -4104 | U2: =IF(Q2="","",Q2*$F2) -> -844 | V2: =IF(R2="","",R2*$F2) -> 2356 | W2: =IF(S2="","",S2*$F2) -> 7956 | X2: 2 Open Box, 1 Brand New | Y2: 3 Unlocked | Z2: Lot is T-Mobile-locked, comps mostly Unlocked - expect a discount
A3: 50424 | B3: iPhone 17 Pro Max | C3: 256GB | D3: A | E3: Generic | F3: 20 | G3: ='Auction Inventory'!L3 -> 818.55 | H3: 9 | I3: 730 | J3: 1000 | K3: 1124.99 | L3: GOOD | M3: 14 | N3: 700 | O3: 885 | P3: =IF(N3="","",N3-$G3) -> -118.55 | Q3: =IF(O3="","",O3-$G3) -> 66.45 | R3: =IF(I3="","",I3*(1-Assumptions!$B$5)-$G3) -> -88.55 | S3: =IF(K3="","",K3*(1-Assumptions!$B$5)-$G3) -> 306.44 | T3: =IF(P3="","",P3*$F3) -> -2371 | U3: =IF(Q3="","",Q3*$F3) -> 1329 | V3: =IF(R3="","",R3*$F3) -> -1771 | W3: =IF(S3="","",S3*$F3) -> 6128.8 | X3: 8 Pre-Owned, 1 Excellent - Refurbished | Y3: 6 Unlocked, 2 Verizon, 1 AT&T
A4: 50429 | B4: iPhone 17 Pro | C4: 256GB | D4: B | E4: Generic | F4: 20 | G4: ='Auction Inventory'!L4 -> 665.55 | H4: 1 | I4: 900 | J4: 900 | K4: 900 | P4: =IF(N4="","",N4-$G4) | Q4: =IF(O4="","",O4-$G4) | R4: =IF(I4="","",I4*(1-Assumptions!$B$5)-$G4) -> 234.45 | S4: =IF(K4="","",K4*(1-Assumptions!$B$5)-$G4) -> 234.45 | T4: =IF(P4="","",P4*$F4) | U4: =IF(Q4="","",Q4*$F4) | V4: =IF(R4="","",R4*$F4) -> 4689 | W4: =IF(S4="","",S4*$F4) -> 4689 | X4: 1 Pre-Owned | Y4: 1 Unlocked | Z4: Thin: 1 comp(s)
A5: 50423 | B5: iPhone 17 | C5: 512GB | D5: A | E5: T-Mobile | F5: 20 | G5: ='Auction Inventory'!L5 -> 563.55 | P5: =IF(N5="","",N5-$G5) | Q5: =IF(O5="","",O5-$G5) | R5: =IF(I5="","",I5*(1-Assumptions!$B$5)-$G5) | S5: =IF(K5="","",K5*(1-Assumptions!$B$5)-$G5) | T5: =IF(P5="","",P5*$F5) | U5: =IF(Q5="","",Q5*$F5) | V5: =IF(R5="","",R5*$F5) | W5: =IF(S5="","",S5*$F5) | Z5: No comp on this page set for this model + storage
A6: 50427 | B6: iPhone 17 | C6: 256GB | D6: A | E6: AT&T | F6: 20 | G6: ='Auction Inventory'!L6 -> 433.5 | H6: 10 | I6: 450 | J6: 576.5 | K6: 784.45 | P6: =IF(N6="","",N6-$G6) | Q6: =IF(O6="","",O6-$G6) | R6: =IF(I6="","",I6*(1-Assumptions!$B$5)-$G6) -> 16.5 | S6: =IF(K6="","",K6*(1-Assumptions!$B$5)-$G6) -> 350.95 | T6: =IF(P6="","",P6*$F6) | U6: =IF(Q6="","",Q6*$F6) | V6: =IF(R6="","",R6*$F6) -> 330 | W6: =IF(S6="","",S6*$F6) -> 7019 | X6: 6 Pre-Owned, 4 Excellent - Refurbished | Y6: 7 Unlocked, 1 T-Mobile, 1 Not stated | Z6: Lot is AT&T-locked, comps mostly Unlocked - expect a discount
A7: 50422 | B7: iPhone 17 | C7: 256GB | D7: B | E7: AT&T | F7: 20 | G7: ='Auction Inventory'!L7 -> 408 | H7: 6 | I7: 450 | J7: 515 | K7: 700 | P7: =IF(N7="","",N7-$G7) | Q7: =IF(O7="","",O7-$G7) | R7: =IF(I7="","",I7*(1-Assumptions!$B$5)-$G7) -> 42 | S7: =IF(K7="","",K7*(1-Assumptions!$B$5)-$G7) -> 292 | T7: =IF(P7="","",P7*$F7) | U7: =IF(Q7="","",Q7*$F7) | V7: =IF(R7="","",R7*$F7) -> 840 | W7: =IF(S7="","",S7*$F7) -> 5840 | X7: 6 Pre-Owned | Y7: 4 Unlocked, 1 T-Mobile, 1 Not stated | Z7: Lot is AT&T-locked, comps mostly Unlocked - expect a discount
A8: 50428 | B8: iPhone 17 | C8: 256GB | D8: C | E8: AT&T | F8: 20 | G8: ='Auction Inventory'!L8 -> 397.8 | H8: 6 | I8: 450 | J8: 515 | K8: 700 | P8: =IF(N8="","",N8-$G8) | Q8: =IF(O8="","",O8-$G8) | R8: =IF(I8="","",I8*(1-Assumptions!$B$5)-$G8) -> 52.2 | S8: =IF(K8="","",K8*(1-Assumptions!$B$5)-$G8) -> 302.2 | T8: =IF(P8="","",P8*$F8) | U8: =IF(Q8="","",Q8*$F8) | V8: =IF(R8="","",R8*$F8) -> 1044 | W8: =IF(S8="","",S8*$F8) -> 6044 | X8: 6 Pre-Owned | Y8: 4 Unlocked, 1 T-Mobile, 1 Not stated | Z8: Lot is AT&T-locked, comps mostly Unlocked - expect a discount
A9: 50412 | B9: iPhone 16 Pro Max | C9: 1TB | D9: C | E9: AT&T | F9: 20 | G9: ='Auction Inventory'!L9 -> 612 | H9: 3 | I9: 839.99 | J9: 850 | K9: 924.99 | P9: =IF(N9="","",N9-$G9) | Q9: =IF(O9="","",O9-$G9) | R9: =IF(I9="","",I9*(1-Assumptions!$B$5)-$G9) -> 227.99 | S9: =IF(K9="","",K9*(1-Assumptions!$B$5)-$G9) -> 312.99 | T9: =IF(P9="","",P9*$F9) | U9: =IF(Q9="","",Q9*$F9) | V9: =IF(R9="","",R9*$F9) -> 4559.8 | W9: =IF(S9="","",S9*$F9) -> 6259.8 | X9: 2 Pre-Owned, 1 Good - Refurbished | Y9: 2 Unlocked, 1 Xfinity | Z9: Lot is AT&T-locked, comps mostly Unlocked - expect a discount
A10: 50416 | B10: iPhone 16 Pro Max | C10: 512GB | D10: A | E10: AT&T | F10: 20 | G10: ='Auction Inventory'!L10 -> 612 | H10: 2 | I10: 420 | J10: 635 | K10: 850 | P10: =IF(N10="","",N10-$G10) | Q10: =IF(O10="","",O10-$G10) | R10: =IF(I10="","",I10*(1-Assumptions!$B$5)-$G10) -> -192 | S10: =IF(K10="","",K10*(1-Assumptions!$B$5)-$G10) -> 238 | T10: =IF(P10="","",P10*$F10) | U10: =IF(Q10="","",Q10*$F10) | V10: =IF(R10="","",R10*$F10) -> -3840 | W10: =IF(S10="","",S10*$F10) -> 4760 | X10: 2 Pre-Owned | Y10: 1 AT&T, 1 Unlocked | Z10: Thin: 2 comp(s)
A11: 50411 | B11: iPhone 16 Pro Max | C11: 256GB | D11: A | E11: Generic | F11: 20 | G11: ='Auction Inventory'!L11 -> 568.65 | H11: 5 | I11: 709.99 | J11: 720 | K11: 850 | P11: =IF(N11="","",N11-$G11) | Q11: =IF(O11="","",O11-$G11) | R11: =IF(I11="","",I11*(1-Assumptions!$B$5)-$G11) -> 141.34 | S11: =IF(K11="","",K11*(1-Assumptions!$B$5)-$G11) -> 281.35 | T11: =IF(P11="","",P11*$F11) | U11: =IF(Q11="","",Q11*$F11) | V11: =IF(R11="","",R11*$F11) -> 2826.8 | W11: =IF(S11="","",S11*$F11) -> 5627 | X11: 5 Pre-Owned | Y11: 5 Unlocked
A12: 50417 | B12: iPhone 16 Pro Max | C12: 256GB | D12: B | E12: Generic | F12: 20 | G12: ='Auction Inventory'!L12 -> 520.2 | H12: 7 | I12: 709.99 | J12: 775 | K12: 850 | P12: =IF(N12="","",N12-$G12) | Q12: =IF(O12="","",O12-$G12) | R12: =IF(I12="","",I12*(1-Assumptions!$B$5)-$G12) -> 189.79 | S12: =IF(K12="","",K12*(1-Assumptions!$B$5)-$G12) -> 329.8 | T12: =IF(P12="","",P12*$F12) | U12: =IF(Q12="","",Q12*$F12) | V12: =IF(R12="","",R12*$F12) -> 3795.8 | W12: =IF(S12="","",S12*$F12) -> 6596 | X12: 5 Pre-Owned, 2 Very Good - Refurbished | Y12: 7 Unlocked
A13: 50410 | B13: iPhone 16 Pro | C13: 512GB | D13: B | E13: T-Mobile | F13: 20 | G13: ='Auction Inventory'!L13 -> 455.838 | H13: 1 | I13: 800 | J13: 800 | K13: 800 | P13: =IF(N13="","",N13-$G13) | Q13: =IF(O13="","",O13-$G13) | R13: =IF(I13="","",I13*(1-Assumptions!$B$5)-$G13) -> 344.162 | S13: =IF(K13="","",K13*(1-Assumptions!$B$5)-$G13) -> 344.162 | T13: =IF(P13="","",P13*$F13) | U13: =IF(Q13="","",Q13*$F13) | V13: =IF(R13="","",R13*$F13) -> 6883.24 | W13: =IF(S13="","",S13*$F13) -> 6883.24 | X13: 1 Very Good - Refurbished | Y13: 1 Unlocked | Z13: Lot is T-Mobile-locked, comps mostly Unlocked - expect a discount | Thin: 1 comp(s)
A14: 50415 | B14: iPhone 16 Plus | C14: 256GB | D14: B | E14: T-Mobile | F14: 20 | G14: ='Auction Inventory'!L14 -> 378.675 | H14: 3 | I14: 450 | J14: 559.99 | K14: 637.99 | P14: =IF(N14="","",N14-$G14) | Q14: =IF(O14="","",O14-$G14) | R14: =IF(I14="","",I14*(1-Assumptions!$B$5)-$G14) -> 71.325 | S14: =IF(K14="","",K14*(1-Assumptions!$B$5)-$G14) -> 259.315 | T14: =IF(P14="","",P14*$F14) | U14: =IF(Q14="","",Q14*$F14) | V14: =IF(R14="","",R14*$F14) -> 1426.5 | W14: =IF(S14="","",S14*$F14) -> 5186.3 | X14: 2 Pre-Owned, 1 Very Good - Refurbished | Y14: 3 Unlocked | Z14: Lot is T-Mobile-locked, comps mostly Unlocked - expect a discount
A15: 50420 | B15: iPhone 16 Plus | C15: 256GB | D15: B | E15: AT&T | F15: 20 | G15: ='Auction Inventory'!L15 -> 313.65 | H15: 3 | I15: 450 | J15: 559.99 | K15: 637.99 | P15: =IF(N15="","",N15-$G15) | Q15: =IF(O15="","",O15-$G15) | R15: =IF(I15="","",I15*(1-Assumptions!$B$5)-$G15) -> 136.35 | S15: =IF(K15="","",K15*(1-Assumptions!$B$5)-$G15) -> 324.34 | T15: =IF(P15="","",P15*$F15) | U15: =IF(Q15="","",Q15*$F15) | V15: =IF(R15="","",R15*$F15) -> 2727 | W15: =IF(S15="","",S15*$F15) -> 6486.8 | X15: 2 Pre-Owned, 1 Very Good - Refurbished | Y15: 3 Unlocked | Z15: Lot is AT&T-locked, comps mostly Unlocked - expect a discount
A16: 50414 | B16: iPhone 16 Plus | C16: 128GB | D16: A | E16: AT&T | F16: 20 | G16: ='Auction Inventory'!L16 -> 410.55 | H16: 3 | I16: 389.95 | J16: 400 | K16: 499.95 | P16: =IF(N16="","",N16-$G16) | Q16: =IF(O16="","",O16-$G16) | R16: =IF(I16="","",I16*(1-Assumptions!$B$5)-$G16) -> -20.6 | S16: =IF(K16="","",K16*(1-Assumptions!$B$5)-$G16) -> 89.4 | T16: =IF(P16="","",P16*$F16) | U16: =IF(Q16="","",Q16*$F16) | V16: =IF(R16="","",R16*$F16) -> -412 | W16: =IF(S16="","",S16*$F16) -> 1788 | X16: 3 Pre-Owned | Y16: 2 Unlocked, 1 Verizon | Z16: Lot is AT&T-locked, comps mostly Unlocked - expect a discount
A17: 50409 | B17: iPhone 16 Plus | C17: 128GB | D17: C | E17: Generic | F17: 20 | G17: ='Auction Inventory'!L17 -> 281.775 | H17: 3 | I17: 389.95 | J17: 400 | K17: 499.95 | P17: =IF(N17="","",N17-$G17) | Q17: =IF(O17="","",O17-$G17) | R17: =IF(I17="","",I17*(1-Assumptions!$B$5)-$G17) -> 108.175 | S17: =IF(K17="","",K17*(1-Assumptions!$B$5)-$G17) -> 218.175 | T17: =IF(P17="","",P17*$F17) | U17: =IF(Q17="","",Q17*$F17) | V17: =IF(R17="","",R17*$F17) -> 2163.5 | W17: =IF(S17="","",S17*$F17) -> 4363.5 | X17: 3 Pre-Owned | Y17: 2 Unlocked, 1 Verizon
A18: 50419 | B18: iPhone 16 | C18: 256GB | D18: B | E18: T-Mobile | F18: 20 | G18: ='Auction Inventory'!L18 -> 291.975 | H18: 2 | I18: 519 | J18: 534.5 | K18: 549.99 | P18: =IF(N18="","",N18-$G18) | Q18: =IF(O18="","",O18-$G18) | R18: =IF(I18="","",I18*(1-Assumptions!$B$5)-$G18) -> 227.025 | S18: =IF(K18="","",K18*(1-Assumptions!$B$5)-$G18) -> 258.015 | T18: =IF(P18="","",P18*$F18) | U18: =IF(Q18="","",Q18*$F18) | V18: =IF(R18="","",R18*$F18) -> 4540.5 | W18: =IF(S18="","",S18*$F18) -> 5160.3 | X18: 2 Pre-Owned | Y18: 2 Unlocked | Z18: Lot is T-Mobile-locked, comps mostly Unlocked - expect a discount | Thin: 2 comp(s)
A19: 50348 | B19: iPhone 16 | C19: 128GB | D19: C | E19: T-Mobile | F19: 246 | G19: ='Auction Inventory'!L19 -> 265.2 | P19: =IF(N19="","",N19-$G19) | Q19: =IF(O19="","",O19-$G19) | R19: =IF(I19="","",I19*(1-Assumptions!$B$5)-$G19) | S19: =IF(K19="","",K19*(1-Assumptions!$B$5)-$G19) | T19: =IF(P19="","",P19*$F19) | U19: =IF(Q19="","",Q19*$F19) | V19: =IF(R19="","",R19*$F19) | W19: =IF(S19="","",S19*$F19) | Z19: No comp on this page set for this model + storage
A20: 50426 | B20: iPhone 16e | C20: 256GB | D20: B | E20: T-Mobile | F20: 20 | G20: ='Auction Inventory'!L20 -> 269.127 | H20: 2 | I20: 299.98 | J20: 364.15 | K20: 428.33 | P20: =IF(N20="","",N20-$G20) | Q20: =IF(O20="","",O20-$G20) | R20: =IF(I20="","",I20*(1-Assumptions!$B$5)-$G20) -> 30.853 | S20: =IF(K20="","",K20*(1-Assumptions!$B$5)-$G20) -> 159.203 | T20: =IF(P20="","",P20*$F20) | U20: =IF(Q20="","",Q20*$F20) | V20: =IF(R20="","",R20*$F20) -> 617.06 | W20: =IF(S20="","",S20*$F20) -> 3184.06 | X20: 1 Very Good - Refurbished, 1 Pre-Owned | Y20: 1 Unlocked, 1 T-Mobile | Z20: Thin: 2 comp(s)
A21: 50421 | B21: iPhone 16e | C21: 256GB | D21: C | E21: T-Mobile | F21: 20 | G21: ='Auction Inventory'!L21 -> 194.004 | H21: 1 | I21: 299.98 | J21: 299.98 | K21: 299.98 | P21: =IF(N21="","",N21-$G21) | Q21: =IF(O21="","",O21-$G21) | R21: =IF(I21="","",I21*(1-Assumptions!$B$5)-$G21) -> 105.976 | S21: =IF(K21="","",K21*(1-Assumptions!$B$5)-$G21) -> 105.976 | T21: =IF(P21="","",P21*$F21) | U21: =IF(Q21="","",Q21*$F21) | V21: =IF(R21="","",R21*$F21) -> 2119.52 | W21: =IF(S21="","",S21*$F21) -> 2119.52 | X21: 1 Pre-Owned | Y21: 1 T-Mobile | Z21: Thin: 1 comp(s)
A22: 50369 | B22: iPhone 16e | C22: 128GB | D22: New | E22: T-Mobile | F22: 20 | G22: ='Auction Inventory'!L22 -> 309.825 | H22: 1 | I22: 419.55 | J22: 419.55 | K22: 419.55 | P22: =IF(N22="","",N22-$G22) | Q22: =IF(O22="","",O22-$G22) | R22: =IF(I22="","",I22*(1-Assumptions!$B$5)-$G22) -> 109.725 | S22: =IF(K22="","",K22*(1-Assumptions!$B$5)-$G22) -> 109.725 | T22: =IF(P22="","",P22*$F22) | U22: =IF(Q22="","",Q22*$F22) | V22: =IF(R22="","",R22*$F22) -> 2194.5 | W22: =IF(S22="","",S22*$F22) -> 2194.5 | X22: 1 Open Box | Y22: 1 Unlocked | Z22: Lot is T-Mobile-locked, comps mostly Unlocked - expect a discount | Thin: 1 comp(s)
A23: 50408 | B23: iPhone 15 Pro Max | C23: 512GB | D23: B | E23: T-Mobile | F23: 20 | G23: ='Auction Inventory'!L23 -> 518.67 | H23: 5 | I23: 500 | J23: 550 | K23: 600 | P23: =IF(N23="","",N23-$G23) | Q23: =IF(O23="","",O23-$G23) | R23: =IF(I23="","",I23*(1-Assumptions!$B$5)-$G23) -> -18.67 | S23: =IF(K23="","",K23*(1-Assumptions!$B$5)-$G23) -> 81.33 | T23: =IF(P23="","",P23*$F23) | U23: =IF(Q23="","",Q23*$F23) | V23: =IF(R23="","",R23*$F23) -> -373.4 | W23: =IF(S23="","",S23*$F23) -> 1626.6 | X23: 5 Pre-Owned | Y23: 2 Not stated, 1 Spectrum, 1 AT&T | Z23: Lot is T-Mobile-locked, comps mostly Unlocked - expect a discount
A24: 50407 | B24: iPhone 15 Pro Max | C24: 512GB | D24: C | E24: AT&T | F24: 20 | G24: ='Auction Inventory'!L24 -> 346.8 | H24: 5 | I24: 500 | J24: 550 | K24: 600 | P24: =IF(N24="","",N24-$G24) | Q24: =IF(O24="","",O24-$G24) | R24: =IF(I24="","",I24*(1-Assumptions!$B$5)-$G24) -> 153.2 | S24: =IF(K24="","",K24*(1-Assumptions!$B$5)-$G24) -> 253.2 | T24: =IF(P24="","",P24*$F24) | U24: =IF(Q24="","",Q24*$F24) | V24: =IF(R24="","",R24*$F24) -> 3064 | W24: =IF(S24="","",S24*$F24) -> 5064 | X24: 5 Pre-Owned | Y24: 2 Not stated, 1 Spectrum, 1 AT&T
A25: 50406 | B25: iPhone 15 Pro Max | C25: 256GB | D25: A | E25: Generic | F25: 20 | G25: ='Auction Inventory'!L25 -> 367.2 | H25: 9 | I25: 495 | J25: 549 | K25: 580 | P25: =IF(N25="","",N25-$G25) | Q25: =IF(O25="","",O25-$G25) | R25: =IF(I25="","",I25*(1-Assumptions!$B$5)-$G25) -> 127.8 | S25: =IF(K25="","",K25*(1-Assumptions!$B$5)-$G25) -> 212.8 | T25: =IF(P25="","",P25*$F25) | U25: =IF(Q25="","",Q25*$F25) | V25: =IF(R25="","",R25*$F25) -> 2556 | W25: =IF(S25="","",S25*$F25) -> 4256 | X25: 9 Pre-Owned | Y25: 9 Unlocked
A26: 50400 | B26: iPhone 15 Pro Max | C26: 256GB | D26: B | E26: Generic | F26: 20 | G26: ='Auction Inventory'!L26 -> 436.05 | H26: 11 | I26: 495 | J26: 549.99 | K26: 671.51 | P26: =IF(N26="","",N26-$G26) | Q26: =IF(O26="","",O26-$G26) | R26: =IF(I26="","",I26*(1-Assumptions!$B$5)-$G26) -> 58.95 | S26: =IF(K26="","",K26*(1-Assumptions!$B$5)-$G26) -> 235.46 | T26: =IF(P26="","",P26*$F26) | U26: =IF(Q26="","",Q26*$F26) | V26: =IF(R26="","",R26*$F26) -> 1179 | W26: =IF(S26="","",S26*$F26) -> 4709.2 | X26: 9 Pre-Owned, 2 Very Good - Refurbished | Y26: 11 Unlocked
A27: 50343 | B27: iPhone 15 Pro Max | C27: 256GB | D27: C | E27: T-Mobile | F27: 250 | G27: ='Auction Inventory'!L27 -> 346.8 | H27: 10 | I27: 495 | J27: 549.5 | K27: 599.99 | P27: =IF(N27="","",N27-$G27) | Q27: =IF(O27="","",O27-$G27) | R27: =IF(I27="","",I27*(1-Assumptions!$B$5)-$G27) -> 148.2 | S27: =IF(K27="","",K27*(1-Assumptions!$B$5)-$G27) -> 253.19 | T27: =IF(P27="","",P27*$F27) | U27: =IF(Q27="","",Q27*$F27) | V27: =IF(R27="","",R27*$F27) -> 37050 | W27: =IF(S27="","",S27*$F27) -> 63297.5 | X27: 9 Pre-Owned, 1 Good - Refurbished | Y27: 10 Unlocked | Z27: Lot is T-Mobile-locked, comps mostly Unlocked - expect a discount
A28: 50347 | B28: iPhone 15 Pro Max | C28: 256GB | D28: C | E28: T-Mobile | F28: 180 | G28: ='Auction Inventory'!L28 -> 346.8 | H28: 10 | I28: 495 | J28: 549.5 | K28: 599.99 | P28: =IF(N28="","",N28-$G28) | Q28: =IF(O28="","",O28-$G28) | R28: =IF(I28="","",I28*(1-Assumptions!$B$5)-$G28) -> 148.2 | S28: =IF(K28="","",K28*(1-Assumptions!$B$5)-$G28) -> 253.19 | T28: =IF(P28="","",P28*$F28) | U28: =IF(Q28="","",Q28*$F28) | V28: =IF(R28="","",R28*$F28) -> 26676 | W28: =IF(S28="","",S28*$F28) -> 45574.2 | X28: 9 Pre-Owned, 1 Good - Refurbished | Y28: 10 Unlocked | Z28: Lot is T-Mobile-locked, comps mostly Unlocked - expect a discount
A29: 50413 | B29: iPhone 15 Pro | C29: 1TB | D29: C | E29: T-Mobile | F29: 20 | G29: ='Auction Inventory'!L29 -> 255 | P29: =IF(N29="","",N29-$G29) | Q29: =IF(O29="","",O29-$G29) | R29: =IF(I29="","",I29*(1-Assumptions!$B$5)-$G29) | S29: =IF(K29="","",K29*(1-Assumptions!$B$5)-$G29) | T29: =IF(P29="","",P29*$F29) | U29: =IF(Q29="","",Q29*$F29) | V29: =IF(R29="","",R29*$F29) | W29: =IF(S29="","",S29*$F29) | Z29: No comp on this page set for this model + storage
A30: 50399 | B30: iPhone 15 Pro | C30: 256GB | D30: A | E30: AT&T | F30: 20 | G30: ='Auction Inventory'!L30 -> 307.275 | H30: 3 | I30: 450 | J30: 504.99 | K30: 549 | P30: =IF(N30="","",N30-$G30) | Q30: =IF(O30="","",O30-$G30) | R30: =IF(I30="","",I30*(1-Assumptions!$B$5)-$G30) -> 142.725 | S30: =IF(K30="","",K30*(1-Assumptions!$B$5)-$G30) -> 241.725 | T30: =IF(P30="","",P30*$F30) | U30: =IF(Q30="","",Q30*$F30) | V30: =IF(R30="","",R30*$F30) -> 2854.5 | W30: =IF(S30="","",S30*$F30) -> 4834.5 | X30: 3 Pre-Owned | Y30: 2 Unlocked, 1 AT&T | Z30: Lot is AT&T-locked, comps mostly Unlocked - expect a discount
A31: 50405 | B31: iPhone 15 Pro | C31: 128GB | D31: A | E31: AT&T | F31: 20 | G31: ='Auction Inventory'!L31 -> 306 | H31: 4 | I31: 349.99 | J31: 462.5 | K31: 544.99 | P31: =IF(N31="","",N31-$G31) | Q31: =IF(O31="","",O31-$G31) | R31: =IF(I31="","",I31*(1-Assumptions!$B$5)-$G31) -> 43.99 | S31: =IF(K31="","",K31*(1-Assumptions!$B$5)-$G31) -> 238.99 | T31: =IF(P31="","",P31*$F31) | U31: =IF(Q31="","",Q31*$F31) | V31: =IF(R31="","",R31*$F31) -> 879.8 | W31: =IF(S31="","",S31*$F31) -> 4779.8 | X31: 4 Pre-Owned | Y31: 3 Unlocked, 1 AT&T | Z31: Lot is AT&T-locked, comps mostly Unlocked - expect a discount
A32: 50345 | B32: iPhone 15 Pro | C32: 128GB | D32: C | E32: T-Mobile | F32: 240 | G32: ='Auction Inventory'!L32 -> 255 | H32: 4 | I32: 349.99 | J32: 462.5 | K32: 544.99 | P32: =IF(N32="","",N32-$G32) | Q32: =IF(O32="","",O32-$G32) | R32: =IF(I32="","",I32*(1-Assumptions!$B$5)-$G32) -> 94.99 | S32: =IF(K32="","",K32*(1-Assumptions!$B$5)-$G32) -> 289.99 | T32: =IF(P32="","",P32*$F32) | U32: =IF(Q32="","",Q32*$F32) | V32: =IF(R32="","",R32*$F32) -> 22797.6 | W32: =IF(S32="","",S32*$F32) -> 69597.6 | X32: 4 Pre-Owned | Y32: 3 Unlocked, 1 AT&T | Z32: Lot is T-Mobile-locked, comps mostly Unlocked - expect a discount
A33: 50354 | B33: iPhone 15 Pro | C33: 128GB | D33: C | E33: T-Mobile | F33: 118 | G33: ='Auction Inventory'!L33 -> 255 | H33: 4 | I33: 349.99 | J33: 462.5 | K33: 544.99 | P33: =IF(N33="","",N33-$G33) | Q33: =IF(O33="","",O33-$G33) | R33: =IF(I33="","",I33*(1-Assumptions!$B$5)-$G33) -> 94.99 | S33: =IF(K33="","",K33*(1-Assumptions!$B$5)-$G33) -> 289.99 | T33: =IF(P33="","",P33*$F33) | U33: =IF(Q33="","",Q33*$F33) | V33: =IF(R33="","",R33*$F33) -> 11208.82 | W33: =IF(S33="","",S33*$F33) -> 34218.82 | X33: 4 Pre-Owned | Y33: 3 Unlocked, 1 AT&T | Z33: Lot is T-Mobile-locked, comps mostly Unlocked - expect a discount
A34: 50404 | B34: iPhone 15 Plus | C34: 256GB | D34: B | E34: AT&T | F34: 20 | G34: ='Auction Inventory'!L34 -> 219.3 | H34: 1 | I34: 471.45 | J34: 471.45 | K34: 471.45 | P34: =IF(N34="","",N34-$G34) | Q34: =IF(O34="","",O34-$G34) | R34: =IF(I34="","",I34*(1-Assumptions!$B$5)-$G34) -> 252.15 | S34: =IF(K34="","",K34*(1-Assumptions!$B$5)-$G34) -> 252.15 | T34: =IF(P34="","",P34*$F34) | U34: =IF(Q34="","",Q34*$F34) | V34: =IF(R34="","",R34*$F34) -> 5043 | W34: =IF(S34="","",S34*$F34) -> 5043 | X34: 1 Very Good - Refurbished | Y34: 1 Unlocked | Z34: Lot is AT&T-locked, comps mostly Unlocked - expect a discount | Thin: 1 comp(s)
A35: 50397 | B35: iPhone 15 Plus | C35: 128GB | D35: A | E35: AT&T | F35: 20 | G35: ='Auction Inventory'!L35 -> 229.5 | H35: 3 | I35: 360.69 | J35: 399 | K35: 426.99 | P35: =IF(N35="","",N35-$G35) | Q35: =IF(O35="","",O35-$G35) | R35: =IF(I35="","",I35*(1-Assumptions!$B$5)-$G35) -> 131.19 | S35: =IF(K35="","",K35*(1-Assumptions!$B$5)-$G35) -> 197.49 | T35: =IF(P35="","",P35*$F35) | U35: =IF(Q35="","",Q35*$F35) | V35: =IF(R35="","",R35*$F35) -> 2623.8 | W35: =IF(S35="","",S35*$F35) -> 3949.8 | X35: 2 Pre-Owned, 1 Excellent - Refurbished | Y35: 3 Unlocked | Z35: Lot is AT&T-locked, comps mostly Unlocked - expect a discount
A36: 50349 | B36: iPhone 15 Plus | C36: 128GB | D36: C | E36: T-Mobile | F36: 240 | G36: ='Auction Inventory'!L36 -> 219.3 | H36: 3 | I36: 360.69 | J36: 390.99 | K36: 399 | P36: =IF(N36="","",N36-$G36) | Q36: =IF(O36="","",O36-$G36) | R36: =IF(I36="","",I36*(1-Assumptions!$B$5)-$G36) -> 141.39 | S36: =IF(K36="","",K36*(1-Assumptions!$B$5)-$G36) -> 179.7 | T36: =IF(P36="","",P36*$F36) | U36: =IF(Q36="","",Q36*$F36) | V36: =IF(R36="","",R36*$F36) -> 33933.6 | W36: =IF(S36="","",S36*$F36) -> 43128 | X36: 2 Pre-Owned, 1 Good - Refurbished | Y36: 3 Unlocked | Z36: Lot is T-Mobile-locked, comps mostly Unlocked - expect a discount
A37: 50360 | B37: iPhone 15 Plus | C37: 128GB | D37: C | E37: T-Mobile | F37: 71 | G37: ='Auction Inventory'!L37 -> 219.3 | H37: 3 | I37: 360.69 | J37: 390.99 | K37: 399 | P37: =IF(N37="","",N37-$G37) | Q37: =IF(O37="","",O37-$G37) | R37: =IF(I37="","",I37*(1-Assumptions!$B$5)-$G37) -> 141.39 | S37: =IF(K37="","",K37*(1-Assumptions!$B$5)-$G37) -> 179.7 | T37: =IF(P37="","",P37*$F37) | U37: =IF(Q37="","",Q37*$F37) | V37: =IF(R37="","",R37*$F37) -> 10038.69 | W37: =IF(S37="","",S37*$F37) -> 12758.7 | X37: 2 Pre-Owned, 1 Good - Refurbished | Y37: 3 Unlocked | Z37: Lot is T-Mobile-locked, comps mostly Unlocked - expect a discount
A38: 50398 | B38: iPhone 15 Plus | C38: 128GB | D38: C | E38: Generic | F38: 20 | G38: ='Auction Inventory'!L38 -> 235.875 | H38: 3 | I38: 360.69 | J38: 390.99 | K38: 399 | P38: =IF(N38="","",N38-$G38) | Q38: =IF(O38="","",O38-$G38) | R38: =IF(I38="","",I38*(1-Assumptions!$B$5)-$G38) -> 124.815 | S38: =IF(K38="","",K38*(1-Assumptions!$B$5)-$G38) -> 163.125 | T38: =IF(P38="","",P38*$F38) | U38: =IF(Q38="","",Q38*$F38) | V38: =IF(R38="","",R38*$F38) -> 2496.3 | W38: =IF(S38="","",S38*$F38) -> 3262.5 | X38: 2 Pre-Owned, 1 Good - Refurbished | Y38: 3 Unlocked
A39: 50418 | B39: iPhone 15 | C39: 512GB | D39: C | E39: T-Mobile | F39: 20 | G39: ='Auction Inventory'!L39 -> 266.475 | H39: 1 | I39: 399 | J39: 399 | K39: 399 | P39: =IF(N39="","",N39-$G39) | Q39: =IF(O39="","",O39-$G39) | R39: =IF(I39="","",I39*(1-Assumptions!$B$5)-$G39) -> 132.525 | S39: =IF(K39="","",K39*(1-Assumptions!$B$5)-$G39) -> 132.525 | T39: =IF(P39="","",P39*$F39) | U39: =IF(Q39="","",Q39*$F39) | V39: =IF(R39="","",R39*$F39) -> 2650.5 | W39: =IF(S39="","",S39*$F39) -> 2650.5 | X39: 1 Pre-Owned | Y39: 1 Unlocked | Z39: Lot is T-Mobile-locked, comps mostly Unlocked - expect a discount | Thin: 1 comp(s)
A40: 50403 | B40: iPhone 15 | C40: 256GB | D40: C | E40: AT&T | F40: 20 | G40: ='Auction Inventory'!L40 -> 214.2 | H40: 2 | I40: 233.99 | J40: 357 | K40: 480 | P40: =IF(N40="","",N40-$G40) | Q40: =IF(O40="","",O40-$G40) | R40: =IF(I40="","",I40*(1-Assumptions!$B$5)-$G40) -> 19.79 | S40: =IF(K40="","",K40*(1-Assumptions!$B$5)-$G40) -> 265.8 | T40: =IF(P40="","",P40*$F40) | U40: =IF(Q40="","",Q40*$F40) | V40: =IF(R40="","",R40*$F40) -> 395.8 | W40: =IF(S40="","",S40*$F40) -> 5316 | X40: 2 Pre-Owned | Y40: 1 AT&T, 1 Unlocked | Z40: Thin: 2 comp(s)
...

Sheet Summary by Model
A1: Model | B1: Lots | C1: Units | D1: Bulk Price Total | E1: Fee @ 2% | F1: Total Excl. Shipping | G1: Blended Cost Per Unit
A2: iPhone 17 Pro Max | B2: =COUNTIF('Auction Inventory'!$B$2:$B$97,$A2) -> 2 | C2: =SUMIF('Auction Inventory'!$B$2:$B$97,$A2,'Auction Inventory'!$E$2:$E$97) -> 40 | D2: =SUMIF('Auction Inventory'!$B$2:$B$97,$A2,'Auction Inventory'!$H$2:$H$97) -> 37250 | E2: =D2*Assumptions!$B$4 -> 745 | F2: =D2+E2 -> 37995 | G2: =IF(C2=0,"",F2/C2) -> 949.875
A3: iPhone 17 Pro | B3: =COUNTIF('Auction Inventory'!$B$2:$B$97,$A3) -> 1 | C3: =SUMIF('Auction Inventory'!$B$2:$B$97,$A3,'Auction Inventory'!$E$2:$E$97) -> 20 | D3: =SUMIF('Auction Inventory'!$B$2:$B$97,$A3,'Auction Inventory'!$H$2:$H$97) -> 13050 | E3: =D3*Assumptions!$B$4 -> 261 | F3: =D3+E3 -> 13311 | G3: =IF(C3=0,"",F3/C3) -> 665.55
A4: iPhone 17 | B4: =COUNTIF('Auction Inventory'!$B$2:$B$97,$A4) -> 4 | C4: =SUMIF('Auction Inventory'!$B$2:$B$97,$A4,'Auction Inventory'!$E$2:$E$97) -> 80 | D4: =SUMIF('Auction Inventory'!$B$2:$B$97,$A4,'Auction Inventory'!$H$2:$H$97) -> 35350 | E4: =D4*Assumptions!$B$4 -> 707 | F4: =D4+E4 -> 36057 | G4: =IF(C4=0,"",F4/C4) -> 450.7125
A5: iPhone 16 Pro Max | B5: =COUNTIF('Auction Inventory'!$B$2:$B$97,$A5) -> 4 | C5: =SUMIF('Auction Inventory'!$B$2:$B$97,$A5,'Auction Inventory'!$E$2:$E$97) -> 80 | D5: =SUMIF('Auction Inventory'!$B$2:$B$97,$A5,'Auction Inventory'!$H$2:$H$97) -> 45350 | E5: =D5*Assumptions!$B$4 -> 907 | F5: =D5+E5 -> 46257 | G5: =IF(C5=0,"",F5/C5) -> 578.2125
A6: iPhone 16 Pro | B6: =COUNTIF('Auction Inventory'!$B$2:$B$97,$A6) -> 1 | C6: =SUMIF('Auction Inventory'!$B$2:$B$97,$A6,'Auction Inventory'!$E$2:$E$97) -> 20 | D6: =SUMIF('Auction Inventory'!$B$2:$B$97,$A6,'Auction Inventory'!$H$2:$H$97) -> 8938 | E6: =D6*Assumptions!$B$4 -> 178.76 | F6: =D6+E6 -> 9116.76 | G6: =IF(C6=0,"",F6/C6) -> 455.838
A7: iPhone 16 Plus | B7: =COUNTIF('Auction Inventory'!$B$2:$B$97,$A7) -> 4 | C7: =SUMIF('Auction Inventory'!$B$2:$B$97,$A7,'Auction Inventory'!$E$2:$E$97) -> 80 | D7: =SUMIF('Auction Inventory'!$B$2:$B$97,$A7,'Auction Inventory'!$H$2:$H$97) -> 27150 | E7: =D7*Assumptions!$B$4 -> 543 | F7: =D7+E7 -> 27693 | G7: =IF(C7=0,"",F7/C7) -> 346.1625
A8: iPhone 16 | B8: =COUNTIF('Auction Inventory'!$B$2:$B$97,$A8) -> 2 | C8: =SUMIF('Auction Inventory'!$B$2:$B$97,$A8,'Auction Inventory'!$E$2:$E$97) -> 266 | D8: =SUMIF('Auction Inventory'!$B$2:$B$97,$A8,'Auction Inventory'!$H$2:$H$97) -> 69685 | E8: =D8*Assumptions!$B$4 -> 1393.7 | F8: =D8+E8 -> 71078.7 | G8: =IF(C8=0,"",F8/C8) -> 267.21316
A9: iPhone 16e | B9: =COUNTIF('Auction Inventory'!$B$2:$B$97,$A9) -> 3 | C9: =SUMIF('Auction Inventory'!$B$2:$B$97,$A9,'Auction Inventory'!$E$2:$E$97) -> 60 | D9: =SUMIF('Auction Inventory'!$B$2:$B$97,$A9,'Auction Inventory'!$H$2:$H$97) -> 15156 | E9: =D9*Assumptions!$B$4 -> 303.12 | F9: =D9+E9 -> 15459.12 | G9: =IF(C9=0,"",F9/C9) -> 257.652
A10: iPhone 15 Pro Max | B10: =COUNTIF('Auction Inventory'!$B$2:$B$97,$A10) -> 6 | C10: =SUMIF('Auction Inventory'!$B$2:$B$97,$A10,'Auction Inventory'!$E$2:$E$97) -> 510 | D10: =SUMIF('Auction Inventory'!$B$2:$B$97,$A10,'Auction Inventory'!$H$2:$H$97) -> 178920 | E10: =D10*Assumptions!$B$4 -> 3578.4 | F10: =D10+E10 -> 182498.4 | G10: =IF(C10=0,"",F10/C10) -> 357.84
A11: iPhone 15 Pro | B11: =COUNTIF('Auction Inventory'!$B$2:$B$97,$A11) -> 5 | C11: =SUMIF('Auction Inventory'!$B$2:$B$97,$A11,'Auction Inventory'!$E$2:$E$97) -> 418 | D11: =SUMIF('Auction Inventory'!$B$2:$B$97,$A11,'Auction Inventory'!$H$2:$H$97) -> 106525 | E11: =D11*Assumptions!$B$4 -> 2130.5 | F11: =D11+E11 -> 108655.5 | G11: =IF(C11=0,"",F11/C11) -> 259.94139
A12: iPhone 15 Plus | B12: =COUNTIF('Auction Inventory'!$B$2:$B$97,$A12) -> 5 | C12: =SUMIF('Auction Inventory'!$B$2:$B$97,$A12,'Auction Inventory'!$E$2:$E$97) -> 371 | D12: =SUMIF('Auction Inventory'!$B$2:$B$97,$A12,'Auction Inventory'!$H$2:$H$97) -> 80290 | E12: =D12*Assumptions!$B$4 -> 1605.8 | F12: =D12+E12 -> 81895.8 | G12: =IF(C12=0,"",F12/C12) -> 220.7434
A13: iPhone 15 | B13: =COUNTIF('Auction Inventory'!$B$2:$B$97,$A13) -> 6 | C13: =SUMIF('Auction Inventory'!$B$2:$B$97,$A13,'Auction Inventory'!$E$2:$E$97) -> 858 | D13: =SUMIF('Auction Inventory'!$B$2:$B$97,$A13,'Auction Inventory'!$H$2:$H$97) -> 184345 | E13: =D13*Assumptions!$B$4 -> 3686.9 | F13: =D13+E13 -> 188031.9 | G13: =IF(C13=0,"",F13/C13) -> 219.1514
... A32: iPhone XR, iPhone SE (2020), iPhone SE (2022) & More | B32: =COUNTIF('Auction Inventory'!$B$2:$B$97,$A32) -> 1 | C32: =SUMIF('Auction Inventory'!$B$2:$B$97,$A32,'Auction Inventory'!$E$2:$E$97) -> 50 | D32: =SUMIF('Auction Inventory'!$B$2:$B$97,$A32,'Auction Inventory'!$H$2:$H$97) -> 610 | E32: =D32*Assumptions!$B$4 -> 12.2 | F32: =D32+E32 -> 622.2 | G32: =IF(C32=0,"",F32/C32) -> 12.444
A33: TOTAL / BLENDED | B33: =SUM(B2:B32) -> 96 | C33: =SUM(C2:C32) -> 8732 | D33: =SUM(D2:D32) -> 1686225 | E33: =SUM(E2:E32) -> 33724.5 | F33: =SUM(F2:F32) -> 1719949.5 | G33: =IF(C33=0,"",F33/C33) -> 196.97085

Sheet Summary by Grade
A1: Grade | B1: Lots | C1: Units | D1: Bulk Price Total | E1: Fee @ 2% | F1: Total Excl. Shipping | G1: Blended Cost Per Unit
A2: A | B2: =COUNTIF('Auction Inventory'!$D$2:$D$97,$A2) -> 19 | C2: =SUMIF('Auction Inventory'!$D$2:$D$97,$A2,'Auction Inventory'!$E$2:$E$97) -> 402 | D2: =SUMIF('Auction Inventory'!$D$2:$D$97,$A2,'Auction Inventory'!$H$2:$H$97) -> 121020 | E2: =D2*Assumptions!$B$4 -> 2420.4 | F2: =D2+E2 -> 123440.4 | G2: =IF(C2=0,"",F2/C2) -> 307.06567
A3: A/B | B3: =COUNTIF('Auction Inventory'!$D$2:$D$97,$A3) -> 1 | C3: =SUMIF('Auction Inventory'!$D$2:$D$97,$A3,'Auction Inventory'!$E$2:$E$97) -> 30 | D3: =SUMIF('Auction Inventory'!$D$2:$D$97,$A3,'Auction Inventory'!$H$2:$H$97) -> 2550 | E3: =D3*Assumptions!$B$4 -> 51 | F3: =D3+E3 -> 2601 | G3: =IF(C3=0,"",F3/C3) -> 86.7
A4: B | B4: =COUNTIF('Auction Inventory'!$D$2:$D$97,$A4) -> 27 | C4: =SUMIF('Auction Inventory'!$D$2:$D$97,$A4,'Auction Inventory'!$E$2:$E$97) -> 1323 | D4: =SUMIF('Auction Inventory'!$D$2:$D$97,$A4,'Auction Inventory'!$H$2:$H$97) -> 277515 | E4: =D4*Assumptions!$B$4 -> 5550.3 | F4: =D4+E4 -> 283065.3 | G4: =IF(C4=0,"",F4/C4) -> 213.95714
A5: B/C | B5: =COUNTIF('Auction Inventory'!$D$2:$D$97,$A5) -> 2 | C5: =SUMIF('Auction Inventory'!$D$2:$D$97,$A5,'Auction Inventory'!$E$2:$E$97) -> 90 | D5: =SUMIF('Auction Inventory'!$D$2:$D$97,$A5,'Auction Inventory'!$H$2:$H$97) -> 2210 | E5: =D5*Assumptions!$B$4 -> 44.2 | F5: =D5+E5 -> 2254.2 | G5: =IF(C5=0,"",F5/C5) -> 25.046667
A6: C | B6: =COUNTIF('Auction Inventory'!$D$2:$D$97,$A6) -> 45 | C6: =SUMIF('Auction Inventory'!$D$2:$D$97,$A6,'Auction Inventory'!$E$2:$E$97) -> 6847 | D6: =SUMIF('Auction Inventory'!$D$2:$D$97,$A6,'Auction Inventory'!$H$2:$H$97) -> 1255655 | E6: =D6*Assumptions!$B$4 -> 25113.1 | F6: =D6+E6 -> 1280768.1 | G6: =IF(C6=0,"",F6/C6) -> 187.05537
A7: New | B7: =COUNTIF('Auction Inventory'!$D$2:$D$97,$A7) -> 2 | C7: =SUMIF('Auction Inventory'!$D$2:$D$97,$A7,'Auction Inventory'!$E$2:$E$97) -> 40 | D7: =SUMIF('Auction Inventory'!$D$2:$D$97,$A7,'Auction Inventory'!$H$2:$H$97) -> 27275 | E7: =D7*Assumptions!$B$4 -> 545.5 | F7: =D7+E7 -> 27820.5 | G7: =IF(C7=0,"",F7/C7) -> 695.5125
A8: TOTAL / BLENDED | B8: =SUM(B2:B7) -> 96 | C8: =SUM(C2:C7) -> 8732 | D8: =SUM(D2:D7) -> 1686225 | E8: =SUM(E2:E7) -> 33724.5 | F8: =SUM(F2:F7) -> 1719949.5 | G8: =IF(C8=0,"",F8/C8) -> 196.97085

Sheet Summary by Storage
A1: Storage | B1: Lots | C1: Units | D1: Bulk Price Total | E1: Fee @ 2% | F1: Total Excl. Shipping | G1: Blended Cost Per Unit
A2: 128GB | B2: =COUNTIF('Auction Inventory'!$C$2:$C$97,$A2) -> 41 | C2: =SUMIF('Auction Inventory'!$C$2:$C$97,$A2,'Auction Inventory'!$E$2:$E$97) -> 6097 | D2: =SUMIF('Auction Inventory'!$C$2:$C$97,$A2,'Auction Inventory'!$H$2:$H$97) -> 1166355 | E2: =D2*Assumptions!$B$4 -> 23327.1 | F2: =D2+E2 -> 1189682.1 | G2: =IF(C2=0,"",F2/C2) -> 195.12582
A3: 1TB | B3: =COUNTIF('Auction Inventory'!$C$2:$C$97,$A3) -> 2 | C3: =SUMIF('Auction Inventory'!$C$2:$C$97,$A3,'Auction Inventory'!$E$2:$E$97) -> 40 | D3: =SUMIF('Auction Inventory'!$C$2:$C$97,$A3,'Auction Inventory'!$H$2:$H$97) -> 17000 | E3: =D3*Assumptions!$B$4 -> 340 | F3: =D3+E3 -> 17340 | G3: =IF(C3=0,"",F3/C3) -> 433.5
A4: 256GB | B4: =COUNTIF('Auction Inventory'!$C$2:$C$97,$A4) -> 24 | C4: =SUMIF('Auction Inventory'!$C$2:$C$97,$A4,'Auction Inventory'!$E$2:$E$97) -> 870 | D4: =SUMIF('Auction Inventory'!$C$2:$C$97,$A4,'Auction Inventory'!$H$2:$H$97) -> 297777 | E4: =D4*Assumptions!$B$4 -> 5955.54 | F4: =D4+E4 -> 303732.54 | G4: =IF(C4=0,"",F4/C4) -> 349.11786
A5: 512GB | B5: =COUNTIF('Auction Inventory'!$C$2:$C$97,$A5) -> 14 | C5: =SUMIF('Auction Inventory'!$C$2:$C$97,$A5,'Auction Inventory'!$E$2:$E$97) -> 280 | D5: =SUMIF('Auction Inventory'!$C$2:$C$97,$A5,'Auction Inventory'!$H$2:$H$97) -> 106633 | E5: =D5*Assumptions!$B$4 -> 2132.66 | F5: =D5+E5 -> 108765.66 | G5: =IF(C5=0,"",F5/C5) -> 388.44879
A6: 64GB | B6: =COUNTIF('Auction Inventory'!$C$2:$C$97,$A6) -> 8 | C6: =SUMIF('Auction Inventory'!$C$2:$C$97,$A6,'Auction Inventory'!$E$2:$E$97) -> 1210 | D6: =SUMIF('Auction Inventory'!$C$2:$C$97,$A6,'Auction Inventory'!$H$2:$H$97) -> 87530 | E6: =D6*Assumptions!$B$4 -> 1750.6 | F6: =D6+E6 -> 89280.6 | G6: =IF(C6=0,"",F6/C6) -> 73.78562
A7: Mixed / Not specified | B7: =COUNTIF('Auction Inventory'!$C$2:$C$97,$A7) -> 7 | C7: =SUMIF('Auction Inventory'!$C$2:$C$97,$A7,'Auction Inventory'!$E$2:$E$97) -> 235 | D7: =SUMIF('Auction Inventory'!$C$2:$C$97,$A7,'Auction Inventory'!$H$2:$H$97) -> 10930 | E7: =D7*Assumptions!$B$4 -> 218.6 | F7: =D7+E7 -> 11148.6 | G7: =IF(C7=0,"",F7/C7) -> 47.440851
A8: TOTAL / BLENDED | B8: =SUM(B2:B7) -> 96 | C8: =SUM(C2:C7) -> 8732 | D8: =SUM(D2:D7) -> 1686225 | E8: =SUM(E2:E7) -> 33724.5 | F8: =SUM(F2:F7) -> 1719949.5 | G8: =IF(C8=0,"",F8/C8) -> 196.97085

Sheet eBay Comps
A1: iPhone Model | B1: Storage | C1: Condition | D1: Grade Band | E1: Lock | F1: Sold Price | G1: Sold Date | H1: Listing Title
A2: iPhone 17 Pro Max | B2: 1TB | C2: Pre-Owned | D2: Used | E2: Unlocked | F2: 1349.99 | G2: Aug 1, 2026 | H2: Apple iPhone 17 Pro Max - 1 TB - Silver (Unlocked)
A3: iPhone 17 Pro Max | B3: 512GB | C3: Open Box | D3: New | E3: Unlocked | F3: 1199 | G3: Aug 1, 2026 | H3: Apple iPhone 17 Pro Max 512GB Cosmic Orange Unlocked Smartphone
A4: iPhone 17 Pro Max | B4: 512GB | C4: Pre-Owned | D4: Used | E4: Unlocked | F4: 1219.99 | G4: Aug 1, 2026 | H4: Factory Unlocked Apple iPhone 17 Pro Max 512GB Cosmic Orange MFXL4LL/A
A5: iPhone 17 Pro Max | B5: 512GB | C5: Open Box | D5: New | E5: Unlocked | F5: 1442.49 | G5: Aug 1, 2026 | H5: Apple iPhone 17 Pro Max 512GB Orange Unlocked 48MP Open Box (A3257)
A6: iPhone 17 Pro Max | B6: 512GB | C6: Brand New | D6: New | E6: Unlocked | F6: 1479 | G6: Aug 1, 2026 | H6: iphone 17 pro max silver 512gb unlocked (sealed)
A7: iPhone 17 Pro Max | B7: 256GB | C7: Pre-Owned | D7: Used | E7: Verizon | F7: 730 | G7: Aug 1, 2026 | H7: Apple iPhone 17 Pro Max - 256 GB - Silver (Verizon) 100% Battery health
A8: iPhone 17 Pro Max | B8: 256GB | C8: Pre-Owned | D8: Used | E8: Verizon | F8: 890 | G8: Aug 1, 2026 | H8: iPhone 17 Pro Max 256 GB Silver Verizon Pre-owned Excellent
A9: iPhone 17 Pro Max | B9: 256GB | C9: Open Box | D9: New | E9: AT&T | F9: 900 | G9: Aug 1, 2026 | H9: Apple iPhone 17 Pro Max - 256 GB - Cosmic Orange (AT&T)
A10: iPhone 17 Pro Max | B10: 256GB | C10: Open Box | D10: New | E10: Unlocked | F10: 900 | G10: Aug 1, 2026 | H10: apple iphone 17 pro max 256gb
A11: iPhone 17 Pro Max | B11: 256GB | C11: Pre-Owned | D11: Used | E11: Unlocked | F11: 938 | G11: Aug 1, 2026 | H11: Apple iPhone 17 Pro Max | 256GB | eSIM | Cosmic Orange | PRE OWNED!
A12: iPhone 17 Pro Max | B12: 256GB | C12: Pre-Owned | D12: Used | E12: Unlocked | F12: 950 | G12: Aug 1, 2026 | H12: iPhone 17 Pro Max Cosmetic Orange 256GB Unlocked Smartphone
A13: iPhone 17 Pro Max | B13: 256GB | C13: Open Box | D13: New | E13: Unlocked | F13: 975.99 | G13: Aug 1, 2026 | H13: iphone 17 pro max 256gb unlocked✅ silver. (Read Description)
... A423: iPhone Air | B423: 512GB | C423: Open Box | D423: New | E423: Unlocked | F423: 992 | G423: Jan 12, 2026 | H423: Apple iPhone Air - Unlocked 512GB Space Black - New Open Box

Sheet SellCell Cashout
A1: Model | B1: Network | C1: Capacity | D1: Condition | E1: Vendors | F1: Lowest Offer | G1: Median Offer | H1: Highest Offer
A2: iPhone 17 Pro Max | B2: Unlocked | C2: 256GB | D2: MINT | E2: 14 | F2: 780 | G2: 925 | H2: 943
A3: iPhone 17 Pro Max | B3: Unlocked | C3: 256GB | D3: GOOD | E3: 14 | F3: 700 | G3: 860 | H3: 885
A4: iPhone 17 Pro Max | B4: Unlocked | C4: 256GB | D4: POOR | E4: 13 | F4: 285 | G4: 531 | H4: 770
A5: iPhone 17 Pro Max | B5: Unlocked | C5: 256GB | D5: FAULTY | E5: 12 | F5: 85 | G5: 331 | H5: 561
A6: iPhone 17 Pro Max | B6: Unlocked | C6: 512GB | D6: MINT | E6: 14 | F6: 876 | G6: 1025 | H6: 1039
A7: iPhone 17 Pro Max | B7: Unlocked | C7: 512GB | D7: GOOD | E7: 14 | F7: 785 | G7: 960 | H7: 985
A8: iPhone 17 Pro Max | B8: Unlocked | C8: 512GB | D8: POOR | E8: 13 | F8: 295 | G8: 593 | H8: 870
A9: iPhone 17 Pro Max | B9: Unlocked | C9: 512GB | D9: FAULTY | E9: 12 | F9: 90 | G9: 376 | H9: 721
A10: iPhone 17 Pro Max | B10: Unlocked | C10: 1TB | D10: MINT | E10: 13 | F10: 950 | G10: 1090 | H10: 1101
A11: iPhone 17 Pro Max | B11: Unlocked | C11: 1TB | D11: GOOD | E11: 13 | F11: 869 | G11: 1025 | H11: 1050
A12: iPhone 17 Pro Max | B12: Unlocked | C12: 1TB | D12: POOR | E12: 13 | F12: 305 | G12: 633 | H12: 935
A13: iPhone 17 Pro Max | B13: Unlocked | C13: 1TB | D13: FAULTY | E13: 12 | F13: 90 | G13: 425 | H13: 831
A15: Every capture had NETWORK = Unlocked. Capacity and condition are what vary. Captured 2026-08-02 from sellcell.com/phones/apple/iphone-17-pro-max.
